<?xml version="1.0" encoding="utf-8"?>
<!-- This URDF was automatically created by SolidWorks to URDF Exporter! Originally created by Stephen Brawner (brawner@gmail.com) 
     Commit Version: 1.6.0-4-g7f85cfe  Build Version: 1.6.7995.38578
     For more information, please see http://wiki.ros.org/sw_urdf_exporter -->
     

    
<robot
  name="urdf">
  <link
    name="base_link_jaka_right">
    <inertial>
      <origin
        xyz="-9.29811783123569E-15 -2.55351295663786E-14 0.0527140176534378"
        rpy="0 0 0" />
      <mass
        value="2.6517937627355" />
      <inertia
        ixx="0.00459869882416778"
        ixy="1.85752629607686E-17"
        ixz="-2.28219532296407E-15"
        iyy="0.00475862705157852"
        iyz="2.22748606625393E-15"
        izz="0.00370665473180569" />
    </inertial>
    <visual>
      <origin
        xyz="0 0 0"
        rpy="0 0 0" />
      <geometry>
        <mesh
          filename="package://robot_description/meshes/base_link.STL" />
      </geometry>
      <material
        name="">
        <color
          rgba="0.898039215686275 0.917647058823529 0.929411764705882 1" />
      </material>
    </visual>
    <collision>
      <origin
        xyz="0 0 0"
        rpy="0 0 0" />
      <geometry>
        <mesh
          filename="package://robot_description/meshes/base_link.STL" />
      </geometry>
    </collision>
  </link>
  <link
    name="r1_right">
    <inertial>
      <origin
        xyz="-2.45882333965719E-06 -3.29465040194155E-07 0.164278748235391"
        rpy="0 0 0" />
      <mass
        value="1.49114512916891" />
      <inertia
        ixx="0.00305995014021982"
        ixy="1.23264704419555E-07"
        ixz="4.84189826771435E-08"
        iyy="0.00378498860937016"
        iyz="-4.00260806320922E-08"
        izz="0.00212611420638678" />
    </inertial>
    <visual>
      <origin
        xyz="0 0 0"
        rpy="0 0 0" />
      <geometry>
        <mesh
          filename="package://robot_description/meshes/r1.STL" />
      </geometry>
      <material
        name="">
        <color
          rgba="0.898039215686275 0.917647058823529 0.929411764705882 1" />
      </material>
    </visual>
    <collision>
      <origin
        xyz="0 0 0"
        rpy="0 0 0" />
      <geometry>
        <mesh
          filename="package://robot_description/meshes/r1.STL" />
      </geometry>
    </collision>
  </link>
  <joint
    name="r-j1_right"
    type="revolute">
    <origin
      xyz="0 0 0"
      rpy="0 0 0" />
    <parent
      link="base_link_jaka_right" />
    <child
      link="r1_right" />
    <axis
      xyz="0 0 1" />
    <limit
      lower="-6.28"
      upper="6.28"
      effort="0"
      velocity="0" />
  </joint>
  <link
    name="r2_right">
    <inertial>
      <origin
        xyz="-1.73912983857383E-05 -0.045302289186851 0.000758985811080221"
        rpy="0 0 0" />
      <mass
        value="2.7030708005657" />
      <inertia
        ixx="0.00985116104091457"
        ixy="-3.38766701447005E-06"
        ixz="-5.61641753701589E-10"
        iyy="0.00588775168674872"
        iyz="-9.3081179688794E-05"
        izz="0.00748059216406972" />
    </inertial>
    <visual>
      <origin
        xyz="0 0 0"
        rpy="0 0 0" />
      <geometry>
        <mesh
          filename="package://robot_description/meshes/r2.STL" />
      </geometry>
      <material
        name="">
        <color
          rgba="0.898039215686275 0.917647058823529 0.929411764705882 1" />
      </material>
    </visual>
    <collision>
      <origin
        xyz="0 0 0"
        rpy="0 0 0" />
      <geometry>
        <mesh
          filename="package://robot_description/meshes/r2.STL" />
      </geometry>
    </collision>
  </link>
  <joint
    name="r-j2_right"
    type="revolute">
    <origin
      xyz="0 0 0.2075"
      rpy="-1.5708 0 3.1416" />
    <parent
      link="r1_right" />
    <child
      link="r2_right" />
    <axis
      xyz="0 0 1" />
    <limit
      lower="-1.8325"
      upper="1.8325"
      effort="0"
      velocity="0" />
  </joint>
  <link
    name="r3_right">
    <inertial>
      <origin
        xyz="0.00781892928429065 0.000443169688911726 0.236718911077405"
        rpy="0 0 0" />
      <mass
        value="3.54660276963343" />
      <inertia
        ixx="0.0185269491138635"
        ixy="1.22803049215312E-06"
        ixz="-0.000120248225114125"
        iyy="0.0186931698724925"
        iyz="1.68848263469426E-05"
        izz="0.0037520600753781" />
    </inertial>
    <visual>
      <origin
        xyz="0 0 0"
        rpy="0 0 0" />
      <geometry>
        <mesh
          filename="package://robot_description/meshes/r3.STL" />
      </geometry>
      <material
        name="">
        <color
          rgba="0.898039215686275 0.917647058823529 0.929411764705882 1" />
      </material>
    </visual>
    <collision>
      <origin
        xyz="0 0 0"
        rpy="0 0 0" />
      <geometry>
        <mesh
          filename="package://robot_description/meshes/r3.STL" />
      </geometry>
    </collision>
  </link>
  <joint
    name="r-j3_right"
    type="revolute">
    <origin
      xyz="0 0 0"
      rpy="1.5708 0 0" />
    <parent
      link="r2_right" />
    <child
      link="r3_right" />
    <axis
      xyz="0 0 1" />
    <limit
      lower="-6.28"
      upper="6.28"
      effort="0"
      velocity="0" />
  </joint>
  <link
    name="r4_right">
    <inertial>
      <origin
        xyz="0.00464859992891739 -0.0316068183766519 0.000433526857347266"
        rpy="0 0 0" />
      <mass
        value="1.47407492251049" />
      <inertia
        ixx="0.00379436067438255"
        ixy="0.00016058091609879"
        ixz="2.4669928356952E-07"
        iyy="0.00225645571243247"
        iyz="7.77456261983296E-06"
        izz="0.00281220267725995" />
    </inertial>
    <visual>
      <origin
        xyz="0 0 0"
        rpy="0 0 0" />
      <geometry>
        <mesh
          filename="package://robot_description/meshes/r4.STL" />
      </geometry>
      <material
        name="">
        <color
          rgba="0.898039215686275 0.917647058823529 0.929411764705882 1" />
      </material>
    </visual>
    <collision>
      <origin
        xyz="0 0 0"
        rpy="0 0 0" />
      <geometry>
        <mesh
          filename="package://robot_description/meshes/r4.STL" />
      </geometry>
    </collision>
  </link>
  <joint
    name="r-j4_right"
    type="revolute">
    <origin
      xyz="0.00040027 0 0.33028"
      rpy="-1.5708 0 0" />
    <parent
      link="r3_right" />
    <child
      link="r4_right" />
    <axis
      xyz="0 0 1" />
    <limit
      lower="-2.5307"
      upper="0.5235"
      effort="0"
      velocity="0" />
  </joint>
  <link
    name="r5_right">
    <inertial>
      <origin
        xyz="-2.41117716243133E-06 0.00407933088083307 0.183521132961616"
        rpy="0 0 0" />
      <mass
        value="2.28121145937994" />
      <inertia
        ixx="0.00549376131725593"
        ixy="1.63293925681376E-07"
        ixz="1.60661986226837E-07"
        iyy="0.00558037684698877"
        iyz="-0.000384345841898028"
        izz="0.00195950697428381" />
    </inertial>
    <visual>
      <origin
        xyz="0 0 0"
        rpy="0 0 0" />
      <geometry>
        <mesh
          filename="package://robot_description/meshes/r5.STL" />
      </geometry>
      <material
        name="">
        <color
          rgba="0.898039215686275 0.917647058823529 0.929411764705882 1" />
      </material>
    </visual>
    <collision>
      <origin
        xyz="0 0 0"
        rpy="0 0 0" />
      <geometry>
        <mesh
          filename="package://robot_description/meshes/r5.STL" />
      </geometry>
    </collision>
  </link>
  <joint
    name="r-j5_right"
    type="revolute">
    <origin
      xyz="0 0 0"
      rpy="1.5708 0 0" />
    <parent
      link="r4_right" />
    <child
      link="r5_right" />
    <axis
      xyz="0 0 1" />
    <limit
      lower="-6.28"
      upper="6.28"
      effort="0"
      velocity="0" />
  </joint>
  <link
    name="r6_right">
    <inertial>
      <origin
        xyz="-1.79742565914465E-07 -0.0856690489718185 0.00568955612692162"
        rpy="0 0 0" />
      <mass
        value="1.71844746686076" />
      <inertia
        ixx="0.00430059794688191"
        ixy="4.61984898627264E-08"
        ixz="1.07416214264555E-08"
        iyy="0.00153199579327497"
        iyz="-0.000759767652732725"
        izz="0.0041130216134936" />
    </inertial>
    <visual>
      <origin
        xyz="0 0 0"
        rpy="0 0 0" />
      <geometry>
        <mesh
          filename="package://robot_description/meshes/r6.STL" />
      </geometry>
      <material
        name="">
        <color
          rgba="0.898039215686275 0.917647058823529 0.929411764705882 1" />
      </material>
    </visual>
    <collision>
      <origin
        xyz="0 0 0"
        rpy="0 0 0" />
      <geometry>
        <mesh
          filename="package://robot_description/meshes/r6.STL" />
      </geometry>
    </collision>
  </link>
  <joint
    name="r-j6_right"
    type="revolute">
    <origin
      xyz="0 0 0.23494"
      rpy="-1.5708 0 -3.1416" />
    <parent
      link="r5_right" />
    <child
      link="r6_right" />
    <axis
      xyz="0 0 1" />
    <limit
      lower="-1.5707"
      upper="1.5707"
      effort="0"
      velocity="0" />
  </joint>
  <link
    name="rt_right">
    <inertial>
      <origin
        xyz="-2.77555756156289E-17 2.77555756156289E-17 -0.00099999999999989"
        rpy="0 0 0" />
      <mass
        value="0.00155862265526226" />
      <inertia
        ixx="9.71784989903361E-08"
        ixy="-8.44451673424977E-30"
        ixz="-2.13144338371386E-24"
        iyy="9.71784989903361E-08"
        iyz="1.94259206721209E-24"
        izz="1.93317916210497E-07" />
    </inertial>
    <visual>
      <origin
        xyz="0 0 0"
        rpy="0 0 0" />
      <geometry>
        <mesh
          filename="package://robot_description/meshes/rt.STL" />
      </geometry>
      <material
        name="">
        <color
          rgba="0.792156862745098 0.819607843137255 0.933333333333333 1" />
      </material>
    </visual>
    <collision>
      <origin
        xyz="0 0 0"
        rpy="0 0 0" />
      <geometry>
        <mesh
          filename="package://robot_description/meshes/rt.STL" />
      </geometry>
    </collision>
  </link>
  <joint
    name="r_t_right"
    type="fixed">
    <origin
      xyz="0 -0.1559 0"
      rpy="1.5708 0 0" />
    <parent
      link="r6_right" />
    <child
      link="rt_right" />
    <axis
      xyz="0 0 0" />
  </joint>
  
  
  
  
  
  <joint name="fixed_right" type="fixed">
  <origin
   xyz="0  0  0.011"
   rpy="0 0 0" />
  <parent link="rt_right"/>
  <child link="R_hand_base_link"/>
  </joint>
  
 
 <link
    name="R_hand_base_link">
    <inertial>
      <origin
        xyz="0.0019598 0.0025264 0.066047"
        rpy="0 0 0" />
      <mass
        value="0.14143" />
      <inertia
        ixx="7.6663E-05"
        ixy="-1.7709E-06"
        ixz="1.655E-06"
        iyy="0.00012281"
        iyz="2.1712E-06"
        izz="8.3831E-05" />
    </inertial>
    <visual>
      <origin
        xyz="0 0 0"
        rpy="0 0 0" />
      <geometry>
        <mesh
          filename="package://robot_description/meshes/R_hand_base_link.STL" />
      </geometry>
      <material
        name="">
        <color
          rgba="1 1 1 1" />
      </material>
    </visual>
    <collision>
      <origin
        xyz="0 0 0"
        rpy="0 0 0" />
      <geometry>
        <mesh
          filename="package://robot_description/meshes/R_hand_base_link.STL" />
      </geometry>
    </collision>
  </link>
  <link
    name="R_thumb_proximal_base">
    <inertial>
      <origin
        xyz="-0.0048934 0.00019129 -0.00757"
        rpy="0 0 0" />
      <mass
        value="0.0018869" />
      <inertia
        ixx="5.4253E-08"
        ixy="1.068E-08"
        ixz="4.7248E-09"
        iyy="8.3068E-08"
        iyz="-1.1631E-09"
        izz="6.7433E-08" />
    </inertial>
    <visual>
      <origin
        xyz="0 0 0"
        rpy="0 0 0" />
      <geometry>
        <mesh
          filename="package://robot_description/meshes/R_thumb_proximal_base.STL" />
      </geometry>
      <material
        name="">
        <color
          rgba="1 1 1 1" />
      </material>
    </visual>
    <collision>
      <origin
        xyz="0 0 0"
        rpy="0 0 0" />
      <geometry>
        <mesh
          filename="package://robot_description/meshes/R_thumb_proximal_base.STL" />
      </geometry>
    </collision>
  </link>
  <joint
    name="R_thumb_MCP_joint1"
    type="revolute">
    <origin
      xyz="-0.02045 0.01696 0.0691"
      rpy="0 0 0" />
    <parent
      link="R_hand_base_link" />
    <child
      link="R_thumb_proximal_base" />
    <axis
      xyz="0 0 -1" />
    <limit
      lower="0.2"
      upper="1.5"
      effort="50"
      velocity="1" />
  </joint>
  <link
    name="R_thumb_proximal">
    <inertial>
      <origin
        xyz="-0.010364 0.023175 -0.0080386"
        rpy="0 0 0" />
      <mass
        value="0.0066075" />
      <inertia
        ixx="1.8999E-06"
        ixy="7.473E-07"
        ixz="1.107E-09"
        iyy="1.4039E-06"
        iyz="7.7482E-10"
        izz="2.786E-06" />
    </inertial>
    <visual>
      <origin
        xyz="0 0 0"
        rpy="0 0 0" />
      <geometry>
        <mesh
          filename="package://robot_description/meshes/R_thumb_proximal.STL" />
      </geometry>
      <material
        name="">
        <color
          rgba="1 1 1 1" />
      </material>
    </visual>
    <collision>
      <origin
        xyz="0 0 0"
        rpy="0 0 0" />
      <geometry>
        <mesh
          filename="package://robot_description/meshes/R_thumb_proximal.STL" />
      </geometry>
    </collision>
  </link>
  <joint
    name="R_thumb_MCP_joint2"
    type="revolute">
    <origin
      xyz="-0.010374 0.0094148 -0.00925"
      rpy="-1.4416 1.5708 0" />
    <parent
      link="R_thumb_proximal_base" />
    <child
      link="R_thumb_proximal" />
    <axis
      xyz="0 0 1" />
    <limit
      lower="0"
      upper="0.7"
      effort="50"
      velocity="1"  />
  </joint>
  <link
    name="R_thumb_intermediate">
    <inertial>
      <origin
        xyz="0.0022214 0.0094341 -0.0071997"
        rpy="0 0 0" />
      <mass
        value="0.0037847" />
      <inertia
        ixx="3.364E-07"
        ixy="1.0067E-07"
        ixz="-1.7217E-12"
        iyy="3.5734E-07"
        iyz="-4.3768E-12"
        izz="4.6531E-07" />
    </inertial>
    <visual>
      <origin
        xyz="0 0 0"
        rpy="0 0 0" />
      <geometry>
        <mesh
          filename="package://robot_description/meshes/R_thumb_intermediate.STL" />
      </geometry>
      <material
        name="">
        <color
          rgba="1 1 1 1" />
      </material>
    </visual>
    <collision>
      <origin
        xyz="0 0 0"
        rpy="0 0 0" />
      <geometry>
        <mesh
          filename="package://robot_description/meshes/R_thumb_intermediate.STL" />
      </geometry>
    </collision>
  </link>
  <joint
    name="R_thumb_PIP_joint"
    type="revolute">
    <origin
      xyz="-0.029639 0.047514 -0.0008"
      rpy="0 0 0" />
    <parent
      link="R_thumb_proximal" />
    <child
      link="R_thumb_intermediate" />
    <axis
      xyz="0 0 1" />
    <limit
      lower="0"
      upper="1"
      effort="50"
      velocity="1"  />
    <mimic 
        joint="R_thumb_MCP_joint2"
        multiplier="1.6"
        offset="0" />
    
    
  </joint>
  <link
    name="R_thumb_distal">
    <inertial>
      <origin
        xyz="-0.0044398 0.0095447 -0.0060033"
        rpy="0 0 0" />
      <mass
        value="0.0033441" />
      <inertia
        ixx="1.4669E-07"
        ixy="5.6223E-08"
        ixz="1.1758E-10"
        iyy="1.3016E-07"
        iyz="-9.9339E-11"
        izz="2.0026E-07" />
    </inertial>
    <visual>
      <origin
        xyz="0 0 0"
        rpy="0 0 0" />
      <geometry>
        <mesh
          filename="package://robot_description/meshes/R_thumb_distal.STL" />
      </geometry>
      <material
        name="">
        <color
          rgba="1 1 1 1" />
      </material>
    </visual>
    <collision>
      <origin
        xyz="0 0 0"
        rpy="0 0 0" />
      <geometry>
        <mesh
          filename="package://robot_description/meshes/R_thumb_distal.STL" />
      </geometry>
    </collision>
  </link>
  <joint
    name="R_thumb_DIP_joint"
    type="revolute">
    <origin
      xyz="-0.0088725 0.020843 -0.0012"
      rpy="0 0 0" />
    <parent
      link="R_thumb_intermediate" />
    <child
      link="R_thumb_distal" />
    <axis
      xyz="0 0 1" />
    <limit
      lower="0"
      upper="0.7"
      effort="50"
      velocity="1"  />
    <mimic 
        joint="R_thumb_MCP_joint2"
        multiplier="1.0"
        offset="0" />
    
    
  </joint>
  <link
    name="R_index_proximal">
    <inertial>
      <origin
        xyz="0.011932 -0.0013134 -0.0060001"
        rpy="0 0 0" />
      <mass
        value="0.0042403" />
      <inertia
        ixx="2.1172E-07"
        ixy="1.9079E-08"
        ixz="-5.2034E-12"
        iyy="6.6206E-07"
        iyz="-1.7999E-12"
        izz="6.9398E-07" />
    </inertial>
    <visual>
      <origin
        xyz="0 0 0"
        rpy="0 0 0" />
      <geometry>
        <mesh
          filename="package://robot_description/meshes/R_index_proximal.STL" />
      </geometry>
      <material
        name="">
        <color
          rgba="1 1 1 1" />
      </material>
    </visual>
    <collision>
      <origin
        xyz="0 0 0"
        rpy="0 0 0" />
      <geometry>
        <mesh
          filename="package://robot_description/meshes/R_index_proximal.STL" />
      </geometry>
    </collision>
  </link>
  <joint
    name="R_index_MCP_joint"
    type="revolute">
    <origin
      xyz="-0.032268 -0.00028533 0.13653"
      rpy="3.1416 -1.5359 3.1416" />
    <parent
      link="R_hand_base_link" />
    <child
      link="R_index_proximal" />
    <axis
      xyz="0 0 1" />
    <limit
      lower="0"
      upper="1.7"
      effort="50"
      velocity="1"  />
  </joint>
  <link
    name="R_index_distal">
    <inertial>
      <origin
        xyz="0.019667 -0.00092222 -0.005"
        rpy="0 0 0" />
      <mass
        value="0.0045683" />
      <inertia
        ixx="1.073E-07"
        ixy="-1.2255E-07"
        ixz="1.1074E-12"
        iyy="7.4989E-07"
        iyz="4.6654E-13"
        izz="7.8179E-07" />
    </inertial>
    <visual>
      <origin
        xyz="0 0 0"
        rpy="0 0 0" />
      <geometry>
        <mesh
          filename="package://robot_description/meshes/R_index_distal.STL" />
      </geometry>
      <material
        name="">
        <color
          rgba="1 1 1 1" />
      </material>
    </visual>
    <collision>
      <origin
        xyz="0 0 0"
        rpy="0 0 0" />
      <geometry>
        <mesh
          filename="package://robot_description/meshes/R_index_distal.STL" />
      </geometry>
    </collision>
  </link>
  <joint
    name="R_index_DIP_joint"
    type="revolute">
    <origin
      xyz="0.032044 0.0023789 -0.001"
      rpy="0 0 0" />
    <parent
      link="R_index_proximal" />
    <child
      link="R_index_distal" />
    <axis
      xyz="0 0 1" />
    <limit
      lower="0"
      upper="1.6"
      effort="50"
      velocity="1"  />
    <mimic 
        joint="R_index_MCP_joint"
        multiplier="1"
        offset="0" />
    
    
  </joint>
  <link
    name="R_middle_proximal">
    <inertial>
      <origin
        xyz="0.011922 -0.0014058 -0.0060001"
        rpy="0 0 0" />
      <mass
        value="0.0042403" />
      <inertia
        ixx="2.1204E-07"
        ixy="2.2563E-08"
        ixz="-6.7713E-12"
        iyy="6.6173E-07"
        iyz="-1.6683E-12"
        izz="6.9397E-07" />
    </inertial>
    <visual>
      <origin
        xyz="0 0 0"
        rpy="0 0 0" />
      <geometry>
        <mesh
          filename="package://robot_description/meshes/R_middle_proximal.STL" />
      </geometry>
      <material
        name="">
        <color
          rgba="1 1 1 1" />
      </material>
    </visual>
    <collision>
      <origin
        xyz="0 0 0"
        rpy="0 0 0" />
      <geometry>
        <mesh
          filename="package://robot_description/meshes/R_middle_proximal.STL" />
      </geometry>
    </collision>
  </link>
  <joint
    name="R_middle_MCP_joint"
    type="revolute">
    <origin
      xyz="-0.01295 -0.00028533 0.1371"
      rpy="0 -1.5708 0" />
    <parent
      link="R_hand_base_link" />
    <child
      link="R_middle_proximal" />
    <axis
      xyz="0 0 1" />
    <limit
      lower="0"
      upper="1.7"
      effort="50"
      velocity="1"  />
  </joint>
  <link
    name="R_middle_distal">
    <inertial>
      <origin
        xyz="0.020884 -0.00017171 -0.005"
        rpy="0 0 0" />
      <mass
        value="0.0050396" />
      <inertia
        ixx="1.3152E-07"
        ixy="-1.8376E-07"
        ixz="5.9512E-12"
        iyy="9.3317E-07"
        iyz="3.0525E-12"
        izz="9.8384E-07" />
    </inertial>
    <visual>
      <origin
        xyz="0 0 0"
        rpy="0 0 0" />
      <geometry>
        <mesh
          filename="package://robot_description/meshes/R_middle_distal.STL" />
      </geometry>
      <material
        name="">
        <color
          rgba="1 1 1 1" />
      </material>
    </visual>
    <collision>
      <origin
        xyz="0 0 0"
        rpy="0 0 0" />
      <geometry>
        <mesh
          filename="package://robot_description/meshes/R_middle_distal.STL" />
      </geometry>
    </collision>
  </link>
  <joint
    name="R_middle_DIP_joint"
    type="revolute">
    <origin
      xyz="0.032062 0.0021307 -0.001"
      rpy="0 0 0" />
    <parent
      link="R_middle_proximal" />
    <child
      link="R_middle_distal" />
    <axis
      xyz="0 0 1" />
    <limit
      lower="0"
      upper="1.6"
      effort="50"
      velocity="1"  />
    <mimic 
        joint="R_middle_MCP_joint"
        multiplier="1"
        offset="0" />
    
    
  </joint>
  <link
    name="R_ring_proximal">
    <inertial>
      <origin
        xyz="0.011949 -0.0011513 -0.0060001"
        rpy="0 0 0" />
      <mass
        value="0.0042403" />
      <inertia
        ixx="2.1128E-07"
        ixy="1.2962E-08"
        ixz="-6.6232E-12"
        iyy="6.625E-07"
        iyz="-1.9136E-12"
        izz="6.9398E-07" />
    </inertial>
    <visual>
      <origin
        xyz="0 0 0"
        rpy="0 0 0" />
      <geometry>
        <mesh
          filename="package://robot_description/meshes/R_ring_proximal.STL" />
      </geometry>
      <material
        name="">
        <color
          rgba="1 1 1 1" />
      </material>
    </visual>
    <collision>
      <origin
        xyz="0 0 0"
        rpy="0 0 0" />
      <geometry>
        <mesh
          filename="package://robot_description/meshes/R_ring_proximal.STL" />
      </geometry>
    </collision>
  </link>
  <joint
    name="R_ring_MCP_joint"
    type="revolute">
    <origin
      xyz="0.0062872 -0.00028533 0.13691"
      rpy="0 -1.5184 0" />
    <parent
      link="R_hand_base_link" />
    <child
      link="R_ring_proximal" />
    <axis
      xyz="0 0 1" />
    <limit
      lower="0"
      upper="1.7"
      effort="50"
      velocity="1"  />
  </joint>
  <link
    name="R_ring_distal">
    <inertial>
      <origin
        xyz="0.01967 -0.0008418 -0.005"
        rpy="0 0 0" />
      <mass
        value="0.0045683" />
      <inertia
        ixx="1.0832E-07"
        ixy="-1.2518E-07"
        ixz="5.604E-13"
        iyy="7.4885E-07"
        iyz="6.9377E-13"
        izz="7.8177E-07" />
    </inertial>
    <visual>
      <origin
        xyz="0 0 0"
        rpy="0 0 0" />
      <geometry>
        <mesh
          filename="package://robot_description/meshes/R_ring_distal.STL" />
      </geometry>
      <material
        name="">
        <color
          rgba="1 1 1 1" />
      </material>
    </visual>
    <collision>
      <origin
        xyz="0 0 0"
        rpy="0 0 0" />
      <geometry>
        <mesh
          filename="package://robot_description/meshes/R_ring_distal.STL" />
      </geometry>
    </collision>
  </link>
  <joint
    name="R_ring_DIP_joint"
    type="revolute">
    <origin
      xyz="0.032009 0.0028136 -0.001"
      rpy="0 0 0" />
    <parent
      link="R_ring_proximal" />
    <child
      link="R_ring_distal" />
    <axis
      xyz="0 0 1" />
    <limit
      lower="0"
      upper="1.6"
      effort="50"
      velocity="1"  />
    <mimic 
      joint="R_ring_MCP_joint"
      multiplier="1"
      offset="0" />
    
    
    
  </joint>
  <link
    name="R_pinky_proximal">
    <inertial>
      <origin
        xyz="0.011913 -0.0014791 -0.0060002"
        rpy="0 0 0" />
      <mass
        value="0.0042403" />
      <inertia
        ixx="2.1233E-07"
        ixy="2.5328E-08"
        ixz="-6.7743E-12"
        iyy="6.6144E-07"
        iyz="-1.3495E-12"
        izz="6.9397E-07" />
    </inertial>
    <visual>
      <origin
        xyz="0 0 0"
        rpy="0 0 0" />
      <geometry>
        <mesh
          filename="package://robot_description/meshes/R_pinky_proximal.STL" />
      </geometry>
      <material
        name="">
        <color
          rgba="1 1 1 1" />
      </material>
    </visual>
    <collision>
      <origin
        xyz="0 0 0"
        rpy="0 0 0" />
      <geometry>
        <mesh
          filename="package://robot_description/meshes/R_pinky_proximal.STL" />
      </geometry>
    </collision>
  </link>
  <joint
    name="R_pinky_MCP_joint"
    type="revolute">
    <origin
      xyz="0.025488 -0.00028533 0.13571"
      rpy="0 -1.4661 0" />
    <parent
      link="R_hand_base_link" />
    <child
      link="R_pinky_proximal" />
    <axis
      xyz="0 0 1" />
    <limit
      lower="0"
      upper="1.7"
      effort="50"
      velocity="1"  />
  </joint>
  <link
    name="R_pinky_distal">
    <inertial>
      <origin
        xyz="0.016308 -0.0016415 -0.0050031"
        rpy="0 0 0" />
      <mass
        value="0.0035996" />
      <inertia
        ixx="7.5453E-08"
        ixy="-6.0072E-08"
        ixz="6.0332E-11"
        iyy="4.3392E-07"
        iyz="-3.4313E-11"
        izz="4.4867E-07" />
    </inertial>
    <visual>
      <origin
        xyz="0 0 0"
        rpy="0 0 0" />
      <geometry>
        <mesh
          filename="package://robot_description/meshes/R_pinky_distal.STL" />
      </geometry>
      <material
        name="">
        <color
          rgba="1 1 1 1" />
      </material>
    </visual>
    <collision>
      <origin
        xyz="0 0 0"
        rpy="0 0 0" />
      <geometry>
        <mesh
          filename="package://robot_description/meshes/R_pinky_distal.STL" />
      </geometry>
    </collision>
  </link>
  <joint
    name="R_pinky_DIP_joint"
    type="revolute">
    <origin
      xyz="0.032074 0.0019335 -0.001"
      rpy="0 0 0" />
    <parent
      link="R_pinky_proximal" />
    <child
      link="R_pinky_distal" />
    <axis
      xyz="0 0 1" />
    <limit
      lower="0"
      upper="1.6"
      effort="50"
      velocity="1"  />
    <mimic 
        joint="R_pinky_MCP_joint"
        multiplier="1"
        offset="0" />
  </joint>
  
  
  
  
</robot>
